[ 2025-07-02 12:55:01,663 ] - 45 - INFO - error occured in python script [D:\Network Security\push_data.py] line number [41] error message ['Database' object is not callable]
